[2024-10-03 13:01:55] [INFO    ] discord.client: logging in using static token
[2024-10-03 13:01:56] [INFO    ] discord.gateway: Shard ID None has connected to Gateway (Session ID: 2c84a81ae7e0d9615f5b8927721fa870).
[2024-10-03 13:03:51] [INFO    ] discord.voice_state: Connecting to voice...
[2024-10-03 13:03:51] [INFO    ] discord.voice_state: Starting voice handshake... (connection attempt 1)
[2024-10-03 13:03:51] [INFO    ] discord.voice_state: Voice handshake complete. Endpoint found: atlanta6649.discord.media
[2024-10-03 13:03:52] [INFO    ] discord.voice_state: Voice connection complete.
[out_#0:0 @ 0x7fc850002b00] The "all_channel_counts" option is deprecated: accept all channel counts
[2024-10-03 13:03:56] [INFO    ] discord.player: ffmpeg process 153523 successfully terminated with return code of 0.
[2024-10-03 13:03:56] [INFO    ] discord.voice_state: The voice handshake is being terminated for Channel ID 1282390179310469181 (Guild ID 942976325659013120)
[2024-10-03 13:09:12] [INFO    ] discord.voice_state: Connecting to voice...
[2024-10-03 13:09:12] [INFO    ] discord.voice_state: Starting voice handshake... (connection attempt 1)
[2024-10-03 13:09:12] [INFO    ] discord.voice_state: Voice handshake complete. Endpoint found: atlanta6649.discord.media
[2024-10-03 13:09:13] [INFO    ] discord.voice_state: Voice connection complete.
[out_#0:0 @ 0x7f4578002b00] The "all_channel_counts" option is deprecated: accept all channel counts
[2024-10-03 13:09:16] [INFO    ] discord.player: ffmpeg process 154077 successfully terminated with return code of 0.
[2024-10-03 13:09:17] [INFO    ] discord.voice_state: The voice handshake is being terminated for Channel ID 1282390179310469181 (Guild ID 942976325659013120)
[2024-10-03 13:09:24] [INFO    ] discord.voice_state: Connecting to voice...
[2024-10-03 13:09:24] [INFO    ] discord.voice_state: Starting voice handshake... (connection attempt 1)
[2024-10-03 13:09:28] [INFO    ] discord.voice_state: The voice handshake is being terminated for Channel ID 1282390179310469181 (Guild ID 942976325659013120)
[2024-10-03 13:09:54] [INFO    ] discord.voice_state: Timed out connecting to voice
[2024-10-03 13:09:54] [INFO    ] discord.voice_state: The voice handshake is being terminated for Channel ID 1282390179310469181 (Guild ID 942976325659013120)
[2024-10-03 13:09:54] [INFO    ] discord.voice_state: The voice handshake is being terminated for Channel ID 1282390179310469181 (Guild ID 942976325659013120)
[2024-10-03 13:10:24] [ERROR   ] discord.ext.commands.bot: Ignoring exception in command noCoito
Traceback (most recent call last):
  File "/home/ec2-user/.local/lib/python3.9/site-packages/discord/voice_state.py", line 407, in _inner_connect
    await self._wait_for_state(ConnectionFlowState.got_both_voice_updates)
  File "/home/ec2-user/.local/lib/python3.9/site-packages/discord/voice_state.py", line 559, in _wait_for_state
    await sane_wait_for([self._state_event.wait()], timeout=timeout)
  File "/home/ec2-user/.local/lib/python3.9/site-packages/discord/utils.py", line 714, in sane_wait_for
    done, pending = await asyncio.wait(ensured, timeout=timeout, return_when=asyncio.ALL_COMPLETED)
  File "/usr/lib64/python3.9/asyncio/tasks.py", line 413, in wait
    return await _wait(fs, timeout, return_when, loop)
  File "/usr/lib64/python3.9/asyncio/tasks.py", line 525, in _wait
    await waiter
asyncio.exceptions.CancelledError

During handling of the above exception, another exception occurred:

Traceback (most recent call last):
  File "/usr/lib64/python3.9/asyncio/tasks.py", line 490, in wait_for
    return fut.result()
asyncio.exceptions.CancelledError

The above exception was the direct cause of the following exception:

Traceback (most recent call last):
  File "/home/ec2-user/.local/lib/python3.9/site-packages/discord/ext/commands/core.py", line 235, in wrapped
    ret = await coro(*args, **kwargs)
  File "/home/ec2-user/Pericobot/bot.py", line 47, in noCoito
    voiceClient = await channel.connect()
  File "/home/ec2-user/.local/lib/python3.9/site-packages/discord/abc.py", line 1966, in connect
    await voice.connect(timeout=timeout, reconnect=reconnect, self_deaf=self_deaf, self_mute=self_mute)
  File "/home/ec2-user/.local/lib/python3.9/site-packages/discord/voice_client.py", line 305, in connect
    await self._connection.connect(
  File "/home/ec2-user/.local/lib/python3.9/site-packages/discord/voice_state.py", line 380, in connect
    await self._connector
  File "/home/ec2-user/.local/lib/python3.9/site-packages/discord/voice_state.py", line 384, in _wrap_connect
    await self._connect(*args)
  File "/home/ec2-user/.local/lib/python3.9/site-packages/discord/voice_state.py", line 429, in _connect
    await asyncio.wait_for(
  File "/usr/lib64/python3.9/asyncio/tasks.py", line 492, in wait_for
    raise exceptions.TimeoutError() from exc
asyncio.exceptions.TimeoutError

The above exception was the direct cause of the following exception:

Traceback (most recent call last):
  File "/home/ec2-user/.local/lib/python3.9/site-packages/discord/ext/commands/bot.py", line 1366, in invoke
    await ctx.command.invoke(ctx)
  File "/home/ec2-user/.local/lib/python3.9/site-packages/discord/ext/commands/core.py", line 1029, in invoke
    await injected(*ctx.args, **ctx.kwargs)  # type: ignore
  File "/home/ec2-user/.local/lib/python3.9/site-packages/discord/ext/commands/core.py", line 244, in wrapped
    raise CommandInvokeError(exc) from exc
discord.ext.commands.errors.CommandInvokeError: Command raised an exception: TimeoutError: 
[2024-10-03 14:37:41] [INFO    ] discord.gateway: Shard ID None has successfully RESUMED session 2c84a81ae7e0d9615f5b8927721fa870.
[2024-10-03 15:17:31] [INFO    ] discord.gateway: Shard ID None has successfully RESUMED session 2c84a81ae7e0d9615f5b8927721fa870.
[2024-10-03 16:22:04] [ERROR   ] discord.client: Attempting a reconnect in 0.48s
Traceback (most recent call last):
  File "/home/ec2-user/.local/lib/python3.9/site-packages/discord/client.py", line 667, in connect
    await self.ws.poll_event()
  File "/home/ec2-user/.local/lib/python3.9/site-packages/discord/gateway.py", line 648, in poll_event
    raise ConnectionClosed(self.socket, shard_id=self.shard_id, code=code) from None
discord.errors.ConnectionClosed: Shard ID None WebSocket closed with 1000
[2024-10-03 16:22:05] [INFO    ] discord.gateway: Shard ID None has successfully RESUMED session 2c84a81ae7e0d9615f5b8927721fa870.
